Workbook

Sheet dim_absences_grp
A1: CD_GRP_ABS | B1: CD_GRP_ABS_3_CAR | C1: LB_GRP_ABS | D1: CD_TYPE_GRP_ABS | E1: LB_TYPE_GRP_ABS | F1: CD_PERIM_GRP_ABS | G1: DT_MAJ
A2: AD | B2: ADO | C2: Congés d'adoption | D2: N | E2: Non-médical | F2: O | G2: 45623
A3: AI | B3: AIR | C3: Absences irrégulières | D3: N | E3: Non-médical | F3: N | G3: 45623
A4: AR | B4: ARE | C4: Absences à régulariser | D4: N | E4: Non-médical | F4: N | G4: 45623
A5: AST | B5: AST | C5: Astreinte | D5: N | E5: Non-médical | F5: N | G5: 45623
A6: AT | B6: ACT | C6: Accident de travail | D6: M | E6: Médical | F6: O | G6: 45623
A7: CF | B7: CMF | C7: Congés motif familial | D7: N | E7: Non-médical | F7: N | G7: 45623
A8: CLD | B8: CLD | C8: Congés longues durées | D8: M | E8: Médical | F8: O | G8: 45623
A9: CLM | B9: CLM | C9: Congés longue maladie | D9: M | E9: Médical | F9: O | G9: 45623
A10: CON | B10: CBO | C10: Congés bonifiés | D10: N | E10: Non-médical | F10: N | G10: 45623
A11: DIV | B11: DIV | C11: Divers | D11: N | E11: Non-médical | F11: N | G11: 45623
A12: FOR | B12: FOR | C12: Formation pro | D12: N | E12: Non-médical | F12: N | G12: 45623
A13: MAL | B13: MAL | C13: Maladie | D13: M | E13: Médical | F13: O | G13: 45623
... A19: SYN | B19: SYN | C19: Absences syndicales | D19: N | E19: Non-médical | F19: N | G19: 45623

Sheet dim_absences
A1: CD_MAB | B1: LB_MAB | C1: LB_MAB_L | D1: MIN_CD_PER | E1: MAX_CD_PER | F1: SUM_ETP_ABS_REP | G1: CD_TYPE_ABS | H1: LB_TYPE_ABS | I1: CD_PERIM_ABS | J1: CD_GRP_ABS | K1: CD_GRP_ABS_3_CAR | L1: LB_GRP_ABS | M1: CD_TYPE_ABS_BS | N1: LB_TYPE_ABS_BS | O1: CD_GRP_ABS_BS | P1: LB_GRP_ABS_BS | Q1: LB_STAT_ABS | R1: CD_GRP_ABS_BW | S1: LB_GRP_ABS_BW | T1: CD_GRP_ABS_ECM | U1: DT_MAJ
A2: 41 | B2: INVAL INF GUERRE | C2: CONGE D'INVALIDITE POUR INFIRMITE DE GUERRE | G2: M | H2: Médical | I2: O | J2: MAL | K2: =VLOOKUP(Requête1[[#This Row],[CD_GRP_ABS]],dim_absences_grp!A:B,2,0) -> MAL | L2: Maladie | M2: M | N2: Médical | O2: MAL | P2: Maladie | Q2: CONGE D'INVALIDITE POUR INFIRMITE DE GUERRE | R2: 1 | S2: Maladie ordinaire | T2: MAL | U2: 45273
A3: A | B3: ASTREINTE INTERNE | C3: ASTREINTE INTERNE | G3: N | H3: Non-médical | I3: N | J3: AST | K3: =VLOOKUP(Requête1[[#This Row],[CD_GRP_ABS]],dim_absences_grp!A:B,2,0) -> AST | L3: Astreinte | M3: X | N3: Exclu | O3: AST | P3: Astreinte | Q3: ASTREINTES | R3: 7 | S3: Autre | T3: AUTRE | U3: 45273
A4: AC | B4: ACCOMP FIN DE VIE | C4: CONGE D'ACCOMPAGNEMENT FIN DE VIE | D4: 201906 | E4: 202506 | F4: 39.413 | G4: N | H4: Non-médical | I4: N | J4: CF | K4: =VLOOKUP(Requête1[[#This Row],[CD_GRP_ABS]],dim_absences_grp!A:B,2,0) -> CMF | L4: Congés motif familial | M4: X | N4: Exclu | O4: CF | P4: Congés motif familial | Q4: CONGE D'ACCOMPAGNEMENT FIN DE VIE | R4: 7 | S4: Autre | T4: AUTRE | U4: 45273
A5: AD | B5: CONGE D'ADOPTION | C5: CONGE D'ADOPTION | D5: 201901 | E5: 202503 | F5: 38.36 | G5: N | H5: Non-médical | I5: O | J5: AD | K5: =VLOOKUP(Requête1[[#This Row],[CD_GRP_ABS]],dim_absences_grp!A:B,2,0) -> ADO | L5: Congés d'adoption | M5: N | N5: Non-médical | O5: CF | P5: Congés motif familial | Q5: CONGE D'ADOPTION | R5: 5 | S5: Maternité, paternité, adoption | T5: MAT | U5: 45273
A6: AF | B6: ASTREINTE FORFAIT | C6: ASTREINTE FORFAITEE | G6: N | H6: Non-médical | I6: N | J6: AST | K6: =VLOOKUP(Requête1[[#This Row],[CD_GRP_ABS]],dim_absences_grp!A:B,2,0) -> AST | L6: Astreinte | M6: X | N6: Exclu | O6: AST | P6: Astreinte | Q6: ASTREINTES | R6: 7 | S6: Autre | T6: AUTRE | U6: 45273
A7: AI | B7: ABS IRREG | C7: ABSENCE IRREGULIERE | D7: 201901 | E7: 202506 | F7: 7495.488 | G7: N | H7: Non-médical | I7: N | J7: AI | K7: =VLOOKUP(Requête1[[#This Row],[CD_GRP_ABS]],dim_absences_grp!A:B,2,0) -> AIR | L7: Absences irrégulières | M7: X | N7: Exclu | O7: AI | P7: Absences irrégulières | Q7: ABSENCE IRREGULIERE | R7: 7 | S7: Autre | T7: AUTRE | U7: 45273
A8: AL | B8: ACTIVITE LIBERALE | C8: ACTIVITE LIBERALE | G8: N | H8: Non-médical | I8: N | J8: DIV | K8: =VLOOKUP(Requête1[[#This Row],[CD_GRP_ABS]],dim_absences_grp!A:B,2,0) -> DIV | L8: Divers | M8: X | N8: Exclu | O8: DIV | P8: Divers | Q8: ACTIVITE LIBERALE | R8: 7 | S8: Autre | T8: AUTRE | U8: 45273
A9: AO | B9: AST. OPERATIONNELL | C9: ASTREINTE OPERATIONNELLE | G9: N | H9: Non-médical | I9: N | J9: AST | K9: =VLOOKUP(Requête1[[#This Row],[CD_GRP_ABS]],dim_absences_grp!A:B,2,0) -> AST | L9: Astreinte | M9: X | N9: Exclu | O9: AST | P9: Astreinte | Q9: ASTREINTES | R9: 7 | S9: Autre | T9: AUTRE | U9: 45273
A10: AP | B10: ACTI. PEDAGOGIQUE | C10: ACTIVITE PEDAGOGIQUE | G10: N | H10: Non-médical | I10: N | J10: FOR | K10: =VLOOKUP(Requête1[[#This Row],[CD_GRP_ABS]],dim_absences_grp!A:B,2,0) -> FOR | L10: Formation pro | M10: X | N10: Exclu | O10: FOR | P10: Formation pro | Q10: AUTRES ACTIVITES | R10: 7 | S10: Autre | T10: AUTRE | U10: 45273
A11: AR | B11: ABS A REGULARISER | C11: ABSENCE A REGULARISER | D11: 201901 | E11: 202506 | F11: 71.385 | G11: N | H11: Non-médical | I11: N | J11: AR | K11: =VLOOKUP(Requête1[[#This Row],[CD_GRP_ABS]],dim_absences_grp!A:B,2,0) -> ARE | L11: Absences à régulariser | M11: X | N11: Exclu | O11: AR | P11: Absences à régulariser | Q11: ABSENCE A REGULARISER | R11: 7 | S11: Autre | T11: AUTRE | U11: 45273
A12: AS | B12: ASTREINTE SECURITE | C12: ASTREINTE DE SECURITE | G12: N | H12: Non-médical | I12: N | J12: AST | K12: =VLOOKUP(Requête1[[#This Row],[CD_GRP_ABS]],dim_absences_grp!A:B,2,0) -> AST | L12: Astreinte | M12: X | N12: Exclu | O12: AST | P12: Astreinte | Q12: ASTREINTES | R12: 7 | S12: Autre | T12: AUTRE | U12: 45273
A13: AT | B13: ACCIDENT TRAVAIL | C13: ACCIDENT DE TRAVAIL | D13: 201901 | E13: 202506 | F13: 41226.804 | G13: M | H13: Médical | I13: O | J13: AT | K13: =VLOOKUP(Requête1[[#This Row],[CD_GRP_ABS]],dim_absences_grp!A:B,2,0) -> ACT | L13: Accident de travail | M13: M | N13: Médical | O13: AT | P13: Accident de travail | Q13: ACCIDENT DE TRAVAIL | R13: 3 | S13: Accident de travail / accident de trajet | T13: AT_MP | U13: 45273
A14: BA | B14: CGE BONIF ANT-GUY | C14: CONGE BONIFIE ANTILLES-GUYANNE | D14: 201901 | E14: 202506 | F14: 16026.427 | G14: N | H14: Non-médical | I14: N | J14: CON | K14: =VLOOKUP(Requête1[[#This Row],[CD_GRP_ABS]],dim_absences_grp!A:B,2,0) -> CBO | L14: Congés bonifiés | M14: X | N14: Exclu | O14: CON | P14: Congés bonifiés | Q14: CONGE BONIFIE | R14: 7 | S14: Autre | T14: AUTRE | U14: 45273
A15: BM | B15: CGE BONIF MAYOTTE | C15: CONGE BONIFIE MAYOTTE | D15: 201907 | E15: 202409 | F15: 40.368 | G15: N | H15: Non-médical | I15: N | J15: CON | K15: =VLOOKUP(Requête1[[#This Row],[CD_GRP_ABS]],dim_absences_grp!A:B,2,0) -> CBO | L15: Congés bonifiés | M15: X | N15: Exclu | O15: CON | P15: Congés bonifiés | Q15: CONGE BONIFIE | R15: 7 | S15: Autre | T15: AUTRE | U15: 45273
A16: BR | B16: CGE BONIF REUNION | C16: CONGE BONIFIE REUNION | D16: 201901 | E16: 202506 | F16: 1044.531 | G16: N | H16: Non-médical | I16: N | J16: CON | K16: =VLOOKUP(Requête1[[#This Row],[CD_GRP_ABS]],dim_absences_grp!A:B,2,0) -> CBO | L16: Congés bonifiés | M16: X | N16: Exclu | O16: CON | P16: Congés bonifiés | Q16: CONGE BONIFIE | R16: 7 | S16: Autre | T16: AUTRE | U16: 45273
A17: CA | B17: CONGE ANNUEL | C17: CONGE ANNUEL | D17: 201901 | E17: 202504 | F17: 36.311 | G17: N | H17: Non-médical | I17: N | J17: CON | K17: =VLOOKUP(Requête1[[#This Row],[CD_GRP_ABS]],dim_absences_grp!A:B,2,0) -> CBO | L17: Congés bonifiés | M17: X | N17: Exclu | O17: CON | P17: Congés bonifiés | Q17: CONGE ANNUEL | R17: 7 | S17: Autre | T17: AUTRE | U17: 45273
A18: CB | B18: CONGE BONIFIE | C18: CONGE BONIFIE | G18: N | H18: Non-médical | I18: N | J18: CON | K18: =VLOOKUP(Requête1[[#This Row],[CD_GRP_ABS]],dim_absences_grp!A:B,2,0) -> CBO | L18: Congés bonifiés | M18: X | N18: Exclu | O18: CON | P18: Congés bonifiés | Q18: CONGE BONIFIE | R18: 7 | S18: Autre | T18: AUTRE | U18: 45273
A19: CC | B19: CAMPAGNE ELECT | C19: CONGE CAMPAGNE ELECTORALE | D19: 202106 | E19: 202106 | F19: 0.132 | G19: N | H19: Non-médical | I19: N | J19: DIV | K19: =VLOOKUP(Requête1[[#This Row],[CD_GRP_ABS]],dim_absences_grp!A:B,2,0) -> DIV | L19: Divers | M19: X | N19: Exclu | O19: DIV | P19: Divers | Q19: AUTRES CONGES | R19: 7 | S19: Autre | T19: AUTRE | U19: 45273
A20: CF | B20: CONGE FORM REM | C20: CONGE FORMATION REMUNERE | D20: 201901 | E20: 202506 | F20: 5492.104 | G20: N | H20: Non-médical | I20: N | J20: FOR | K20: =VLOOKUP(Requête1[[#This Row],[CD_GRP_ABS]],dim_absences_grp!A:B,2,0) -> FOR | L20: Formation pro | M20: X | N20: Exclu | O20: FOR | P20: Formation pro | Q20: CONGE FORMATION | R20: 7 | S20: Autre | T20: AUTRE | U20: 45273
A21: CG | B21: CONGRES COLLOQUES | C21: ABSENCE CONGRES/COLLOQUES SCIENTIFIQUES | G21: N | H21: Non-médical | I21: N | J21: DIV | K21: =VLOOKUP(Requête1[[#This Row],[CD_GRP_ABS]],dim_absences_grp!A:B,2,0) -> DIV | L21: Divers | M21: X | N21: Exclu | O21: DIV | P21: Divers | Q21: AUTRES ABSENCES | R21: 7 | S21: Autre | T21: AUTRE | U21: 45273
A22: CJ | B22: FORM CAD ANIM JEUN | C22: CONGE DE FORM. CADRES ANIMATEURS LA JEUNESSE | D22: 201904 | E22: 202506 | F22: 4.656 | G22: N | H22: Non-médical | I22: N | J22: FOR | K22: =VLOOKUP(Requête1[[#This Row],[CD_GRP_ABS]],dim_absences_grp!A:B,2,0) -> FOR | L22: Formation pro | M22: X | N22: Exclu | O22: FOR | P22: Formation pro | Q22: AUTRES CONGES | R22: 7 | S22: Autre | T22: AUTRE | U22: 45273
A23: CM | B23: MALADIE ORDINAIRE | C23: MALADIE ORDINAIRE | D23: 201901 | E23: 202506 | F23: 186559.21 | G23: M | H23: Médical | I23: O | J23: MAL | K23: =VLOOKUP(Requête1[[#This Row],[CD_GRP_ABS]],dim_absences_grp!A:B,2,0) -> MAL | L23: Maladie | M23: M | N23: Médical | O23: MAL | P23: Maladie | Q23: MALADIE ORDINAIRE | R23: 1 | S23: Maladie ordinaire | T23: MAL | U23: 45273
A24: CN | B24: CONGE FORM NON REM | C24: CONGE FORMATION NON REMUNERE | D24: 201901 | E24: 202506 | F24: 165.378 | G24: N | H24: Non-médical | I24: N | J24: FOR | K24: =VLOOKUP(Requête1[[#This Row],[CD_GRP_ABS]],dim_absences_grp!A:B,2,0) -> FOR | L24: Formation pro | M24: X | N24: Exclu | O24: FOR | P24: Formation pro | Q24: CONGE FORMATION | R24: 7 | S24: Autre | T24: AUTRE | U24: 45273
A25: CO | B25: CONCOURS | C25: JOURNEE DE CONCOURS | D25: 202203 | E25: 202504 | F25: 0.34 | G25: N | H25: Non-médical | I25: N | J25: DIV | K25: =VLOOKUP(Requête1[[#This Row],[CD_GRP_ABS]],dim_absences_grp!A:B,2,0) -> DIV | L25: Divers | M25: X | N25: Exclu | O25: DIV | P25: Divers | Q25: JOURNEE DE CONCOURS | R25: 7 | S25: Autre | T25: AUTRE | U25: 45273
A26: CP | B26: PRES PARENTALE | C26: CONGE DE PRESENCE PARENTALE | D26: 201901 | E26: 202506 | F26: 2334.609 | G26: N | H26: Non-médical | I26: N | J26: CF | K26: =VLOOKUP(Requête1[[#This Row],[CD_GRP_ABS]],dim_absences_grp!A:B,2,0) -> CMF | L26: Congés motif familial | M26: X | N26: Exclu | O26: CF | P26: Congés motif familial | Q26: CONGE PRESENCE PARENTALE | R26: 7 | S26: Autre | T26: AUTRE | U26: 45273
A27: CS | B27: CONGE SANS REM | C27: CONGE SANS REMUNERATION | D27: 201901 | E27: 202506 | F27: 14234.914 | G27: N | H27: Non-médical | I27: N | J27: DIV | K27: =VLOOKUP(Requête1[[#This Row],[CD_GRP_ABS]],dim_absences_grp!A:B,2,0) -> DIV | L27: Divers | M27: X | N27: Exclu | O27: DIV | P27: Divers | Q27: CONGE SANS REMUNERATION | R27: 7 | S27: Autre | T27: AUTRE | U27: 45273
A28: CT | B28: CPTE EPARGNE TPS | C28: COMPTE EPARGNE TEMPS | D28: 202304 | E28: 202304 | F28: 0.432 | G28: N | H28: Non-médical | I28: N | J28: CON | K28: =VLOOKUP(Requête1[[#This Row],[CD_GRP_ABS]],dim_absences_grp!A:B,2,0) -> CBO | L28: Congés bonifiés | M28: X | N28: Exclu | O28: CON | P28: Congés bonifiés | Q28: COMPTE EPARGNE TEMPS | R28: 7 | S28: Autre | T28: AUTRE | U28: 45273
A29: DS | B29: DONS SANG OU MOELL | C29: JOURNEES DE DONNEUR DE SANG | D29: 201901 | E29: 202503 | F29: 2.138 | G29: N | H29: Non-médical | I29: N | J29: DIV | K29: =VLOOKUP(Requête1[[#This Row],[CD_GRP_ABS]],dim_absences_grp!A:B,2,0) -> DIV | L29: Divers | M29: X | N29: Exclu | O29: DIV | P29: Divers | Q29: AUTRES ABSENCES | R29: 7 | S29: Autre | T29: AUTRE | U29: 45273
A30: EC | B30: EVICTION COVID | C30: EVICTION COVID | G30: N | H30: Non-médical | I30: N | J30: CF | K30: =VLOOKUP(Requête1[[#This Row],[CD_GRP_ABS]],dim_absences_grp!A:B,2,0) -> CMF | L30: Congés motif familial | M30: X | N30: Exclu | O30: CF | P30: Congés motif familial | Q30: EVICTION COVID | R30: 7 | S30: Autre | T30: AUTRE | U30: 45273
A31: EF | B31: EVENEMENT FAMILIAL | C31: EVENEMENT FAMILIAL | D31: 201901 | E31: 202506 | F31: 321.717 | G31: N | H31: Non-médical | I31: N | J31: CF | K31: =VLOOKUP(Requête1[[#This Row],[CD_GRP_ABS]],dim_absences_grp!A:B,2,0) -> CMF | L31: Congés motif familial | M31: X | N31: Exclu | O31: CF | P31: Congés motif familial | Q31: EVENEMENT FAMILIAL | R31: 7 | S31: Autre | T31: AUTRE | U31: 45273
A32: EM | B32: ENFANTS MALADES | C32: ENFANTS MALADES | D32: 201901 | E32: 202506 | F32: 6867.089 | G32: N | H32: Non-médical | I32: N | J32: CF | K32: =VLOOKUP(Requête1[[#This Row],[CD_GRP_ABS]],dim_absences_grp!A:B,2,0) -> CMF | L32: Congés motif familial | M32: X | N32: Exclu | O32: CF | P32: Congés motif familial | Q32: ENFANTS MALADES | R32: 7 | S32: Autre | T32: AUTRE | U32: 45273
A33: ER | B33: ENSEIGN. ET RECH. | C33: ENSEIGNEMENT ET RECHERCHE | G33: N | H33: Non-médical | I33: N | J33: FOR | K33: =VLOOKUP(Requête1[[#This Row],[CD_GRP_ABS]],dim_absences_grp!A:B,2,0) -> FOR | L33: Formation pro | M33: X | N33: Exclu | O33: FOR | P33: Formation pro | Q33: AUTRES ABSENCES | R33: 7 | S33: Autre | T33: AUTRE | U33: 45273
A34: ET | B34: EXCL TEMPORAIRE | C34: EXCLUSION TEMPORAIRE | D34: 201901 | E34: 202506 | F34: 463.482 | G34: N | H34: Non-médical | I34: N | J34: SUS | K34: =VLOOKUP(Requête1[[#This Row],[CD_GRP_ABS]],dim_absences_grp!A:B,2,0) -> SUS | L34: Suspension | M34: X | N34: Exclu | O34: SUS | P34: Suspension | Q34: EXCLUSION TEMPORAIRE | R34: 7 | S34: Autre | T34: AUTRE | U34: 45273
A35: FO | B35: FORMATION CONTINUE | C35: FORMATION PROFESSIONNELLE | D35: 201901 | E35: 202506 | F35: 141.532 | G35: N | H35: Non-médical | I35: N | J35: FOR | K35: =VLOOKUP(Requête1[[#This Row],[CD_GRP_ABS]],dim_absences_grp!A:B,2,0) -> FOR | L35: Formation pro | M35: X | N35: Exclu | O35: FOR | P35: Formation pro | Q35: FORMATION PROFESSIONNELLE | R35: 7 | S35: Autre | T35: AUTRE | U35: 45273
A36: FS | B36: FORMATION SYNDIC | C36: STAGE DE FORMATION SYNDICALE | D36: 201901 | E36: 202506 | F36: 131.405 | G36: N | H36: Non-médical | I36: N | J36: SYN | K36: =VLOOKUP(Requête1[[#This Row],[CD_GRP_ABS]],dim_absences_grp!A:B,2,0) -> SYN | L36: Absences syndicales | M36: X | N36: Exclu | O36: SYN | P36: Absences syndicales | Q36: ACTIVITE SYNDICALE | R36: 7 | S36: Autre | T36: AUTRE | U36: 45273
A37: G | B37: GARDE | C37: GARDE | G37: N | H37: Non-médical | I37: N | J37: DIV | K37: =VLOOKUP(Requête1[[#This Row],[CD_GRP_ABS]],dim_absences_grp!A:B,2,0) -> DIV | L37: Divers | M37: X | N37: Exclu | O37: DIV | P37: Divers | Q37: GARDE | R37: 7 | S37: Autre | T37: AUTRE | U37: 45273
A38: GM | B38: GRAVE MALADIE | C38: CONGE GRAVE MALADIE | D38: 201901 | E38: 202506 | F38: 1101.475 | G38: M | H38: Médical | I38: O | J38: CLM | K38: =VLOOKUP(Requête1[[#This Row],[CD_GRP_ABS]],dim_absences_grp!A:B,2,0) -> CLM | L38: Congés longue maladie | M38: M | N38: Médical | O38: CLM | P38: Congés longue maladie | Q38: CONGE LONGUE MALADIE | R38: 2 | S38: Maladie longue durée | T38: MAL | U38: 45273
A39: GP | B39: GROSSESSE PATHO | C39: GROSSESSE PATHOLOGIQUE | D39: 201901 | E39: 202506 | F39: 9154.394 | G39: M | H39: Médical | I39: O | J39: MAL | K39: =VLOOKUP(Requête1[[#This Row],[CD_GRP_ABS]],dim_absences_grp!A:B,2,0) -> MAL | L39: Maladie | M39: M | N39: Médical | O39: MAL | P39: Maladie | Q39: GROSSESSE PATHOLOGIQUE | R39: 1 | S39: Maladie ordinaire | T39: MAT | U39: 45273
A40: GPP | B40: ACTIVITE INDEM TA | C40: ACTIVITE INDEM TA | G40: N | H40: Non-médical | I40: N | J40: DIV | K40: =VLOOKUP(Requête1[[#This Row],[CD_GRP_ABS]],dim_absences_grp!A:B,2,0) -> DIV | L40: Divers | M40: X | N40: Exclu | O40: DIV | P40: Divers | Q40: AUTRES ACTIVITES | R40: 7 | S40: Autre | T40: AUTRE | U40: 45273
...
